[2024-07-26T06:29:05.849+0000] {local_task_job_runner.py:120} INFO - ::group::Pre task execution logs
[2024-07-26T06:29:05.865+0000] {taskinstance.py:2076} INFO - Dependencies all met for dep_context=non-requeueable deps ti=<TaskInstance: 8_postgres_to_s3_dag.py.postgres_to_s3 manual__2024-07-26T06:29:05.309727+00:00 [queued]>
[2024-07-26T06:29:05.869+0000] {taskinstance.py:2076} INFO - Dependencies all met for dep_context=requeueable deps ti=<TaskInstance: 8_postgres_to_s3_dag.py.postgres_to_s3 manual__2024-07-26T06:29:05.309727+00:00 [queued]>
[2024-07-26T06:29:05.869+0000] {taskinstance.py:2306} INFO - Starting attempt 1 of 6
[2024-07-26T06:29:05.875+0000] {taskinstance.py:2330} INFO - Executing <Task(PythonOperator): postgres_to_s3> on 2024-07-26 06:29:05.309727+00:00
[2024-07-26T06:29:05.878+0000] {warnings.py:112} WARNING - /home/***/.local/lib/python3.12/site-packages/***/task/task_runner/standard_task_runner.py:62: DeprecationWarning: This process (pid=903) is multi-threaded, use of fork() may lead to deadlocks in the child.
  pid = os.fork()

[2024-07-26T06:29:05.879+0000] {standard_task_runner.py:90} INFO - Running: ['***', 'tasks', 'run', '8_postgres_to_s3_dag.py', 'postgres_to_s3', 'manual__2024-07-26T06:29:05.309727+00:00', '--job-id', '21', '--raw', '--subdir', 'DAGS_FOLDER/8_postgres_to_s3_dag.py', '--cfg-path', '/tmp/tmpsm427me2']
[2024-07-26T06:29:05.881+0000] {standard_task_runner.py:91} INFO - Job 21: Subtask postgres_to_s3
[2024-07-26T06:29:05.881+0000] {standard_task_runner.py:64} INFO - Started process 904 to run task
[2024-07-26T06:29:05.906+0000] {task_command.py:426} INFO - Running <TaskInstance: 8_postgres_to_s3_dag.py.postgres_to_s3 manual__2024-07-26T06:29:05.309727+00:00 [running]> on host ecd5bbc03de3
[2024-07-26T06:29:05.949+0000] {taskinstance.py:2648} INFO - Exporting env vars: AIRFLOW_CTX_DAG_OWNER='***' AIRFLOW_CTX_DAG_ID='8_postgres_to_s3_dag.py' AIRFLOW_CTX_TASK_ID='postgres_to_s3' AIRFLOW_CTX_EXECUTION_DATE='2024-07-26T06:29:05.309727+00:00' AIRFLOW_CTX_TRY_NUMBER='1' AIRFLOW_CTX_DAG_RUN_ID='manual__2024-07-26T06:29:05.309727+00:00'
[2024-07-26T06:29:05.950+0000] {taskinstance.py:430} INFO - ::endgroup::
[2024-07-26T06:29:05.962+0000] {base.py:84} INFO - Using connection ID 'postgres_localhost' for task execution.
[2024-07-26T06:29:05.978+0000] {taskinstance.py:441} INFO - ::group::Post task execution logs
[2024-07-26T06:29:05.979+0000] {taskinstance.py:2905} ERROR - Task failed with exception
Traceback (most recent call last):
  File "/home/airflow/.local/lib/python3.12/site-packages/airflow/models/taskinstance.py", line 465, in _execute_task
    result = _execute_callable(context=context, **execute_callable_kwargs)
             ^^^^^^^^^^^^^^^^^^^^^^^^^^^^^^^^^^^^^^^^^^^^^^^^^^^^^^^^^^^^^
  File "/home/airflow/.local/lib/python3.12/site-packages/airflow/models/taskinstance.py", line 432, in _execute_callable
    return execute_callable(context=context, **execute_callable_kwargs)
           ^^^^^^^^^^^^^^^^^^^^^^^^^^^^^^^^^^^^^^^^^^^^^^^^^^^^^^^^^^^^
  File "/home/airflow/.local/lib/python3.12/site-packages/airflow/models/baseoperator.py", line 401, in wrapper
    return func(self, *args, **kwargs)
           ^^^^^^^^^^^^^^^^^^^^^^^^^^^
  File "/home/airflow/.local/lib/python3.12/site-packages/airflow/operators/python.py", line 235, in execute
    return_value = self.execute_callable()
                   ^^^^^^^^^^^^^^^^^^^^^^^
  File "/home/airflow/.local/lib/python3.12/site-packages/airflow/operators/python.py", line 252, in execute_callable
    return self.python_callable(*self.op_args, **self.op_kwargs)
           ^^^^^^^^^^^^^^^^^^^^^^^^^^^^^^^^^^^^^^^^^^^^^^^^^^^^^
  File "/opt/airflow/dags/8_postgres_to_s3_dag.py", line 23, in postgres_to_s3
    with open('dags/get_orders.txt') as f:
         ^^^^^^^^^^^^^^^^^^^^^^^^^^^
FileNotFoundError: [Errno 2] No such file or directory: 'dags/get_orders.txt'
[2024-07-26T06:29:05.983+0000] {taskinstance.py:1206} INFO - Marking task as UP_FOR_RETRY. dag_id=8_postgres_to_s3_dag.py, task_id=postgres_to_s3, run_id=manual__2024-07-26T06:29:05.309727+00:00, execution_date=20240726T062905, start_date=20240726T062905, end_date=20240726T062905
[2024-07-26T06:29:05.987+0000] {standard_task_runner.py:110} ERROR - Failed to execute job 21 for task postgres_to_s3 ([Errno 2] No such file or directory: 'dags/get_orders.txt'; 904)
[2024-07-26T06:29:06.024+0000] {local_task_job_runner.py:243} INFO - Task exited with return code 1
[2024-07-26T06:29:06.031+0000] {taskinstance.py:3503} INFO - 0 downstream tasks scheduled from follow-on schedule check
[2024-07-26T06:29:06.031+0000] {local_task_job_runner.py:222} INFO - ::endgroup::
